{
  "contest": 304,
  "handle": "zhaojie",
  "risk": "2",
  "title": "Cross-chain calls sent from ZetaChain are not recovered if they fail.",
  "issueId": 245,
  "issueUrl": "https://github.com/code-423n4/2023-11-zetachain-findings/issues/245"
}